Workbook

Sheet Léame
A1: Directorio de contactos institucionales – Coahuila
A2: Para la oferta de cursos de Derecho Parlamentario y de la Maestría en Derecho Ambiental, Tecnologías Emergentes y Seguridad Pública (DATESP).
A3: Fecha de integración: 30 de septiembre de 2026.
A5: Cómo usar este archivo
A6: • Hoja 'Directorio': todos los contactos. Usa los filtros de cada columna (Programa, Segmento, Prioridad, Ciudad…).
A7: • Hoja 'Resumen': conteo de contactos por segmento y programa (se actualiza solo).
A8: • Hoja 'Pendientes': contactos que faltan por conseguir y dónde buscarlos.
A9: • Columnas en amarillo (Estatus de contacto, Fecha, Respuesta): llénalas tú al dar seguimiento.
A11: Nivel de confianza
A12: Alta: dato publicado en el sitio oficial de la institución.
A13: Media: dato de directorios oficiales antiguos o de terceros; confirmar por teléfono antes de enviar.
A14: Baja: correo personal/genérico (Gmail, Hotmail) o dato sin fuente oficial; verificar siempre.
... A19: • Recomendación: envía un oficio a la unidad de capacitación con copia al titular y ofrece un convenio o una beca grupal.

Sheet Directorio
A1: # | B1: Programa | C1: Segmento | D1: Prioridad | E1: Institución | F1: Área | G1: Titular | H1: Cargo | I1: Correo electrónico | J1: Teléfono | K1: Ciudad | L1: Dirección | M1: Fuente (URL) | N1: Confianza | O1: Notas | P1: Estatus de contacto | Q1: Fecha de contacto | R1: Respuesta / seguimiento
A2: 1 | B2: Ambos | C2: Legislativo | D2: Alta | E2: Congreso del Estado de Coahuila | F2: Contacto general | I2: contacto@congresocoahuila.gob.mx | J2: (844) 242 11 00 | K2: Saltillo | L2: Blvd. Francisco Coss s/n esq. Obregón, Zona Centro, C.P. 25000 | M2: https://www.congresocoahuila.gob.mx/portal/correo-electronico/ | N2: Alta | O2: LXIII Legislatura termina 31/12/2026; en 2027 entra la nueva. Pedir directorio de diputados electos.
A3: 2 | B3: Derecho Parlamentario | C3: Legislativo | D3: Alta | E3: Congreso del Estado de Coahuila | F3: Webmaster / correo institucional | I3: webmaster@congresocoahuila.gob.mx | J3: (844) 242 11 00 | K3: Saltillo | L3: Blvd. Francisco Coss s/n, Zona Centro | M3: https://www.congresocoahuila.gob.mx/portal/correo-electronico/ | N3: Alta | O3: Usar como respaldo del correo de contacto.
A4: 3 | B4: Derecho Parlamentario | C4: Legislativo | D4: Alta | E4: Congreso del Estado de Coahuila | F4: Instituto de Investigaciones Jurídicas y Parlamentarias | J4: (844) 242 10 39 | K4: Saltillo | L4: Biblioteca del Congreso, Blvd. Francisco Coss y Acuña s/n, Zona Centro | M4: https://www.congresocoahuila.gob.mx/coahuila/congreso.html | N4: Media | O4: Aliado natural para cursos de técnica legislativa. Pedir correo del titular.
A5: 4 | B5: Derecho Parlamentario | C5: Legislativo | D5: Alta | E5: Congreso del Estado de Coahuila | F5: Diputadas y diputados (25) | H5: Diputados LXIII Legislatura | J5: (844) 242 11 00 | K5: Saltillo | M5: https://www.congresocoahuila.gob.mx/portal/diputados/ | N5: Media | O5: Correos individuales en el portal de diputados (sitio bloqueado desde este entorno). Llenar hoja 'Pendientes'.
A6: 5 | B6: Ambos | C6: Fiscalización | D6: Media | E6: Auditoría Superior del Estado de Coahuila (ASEC) | F6: Contacto general | I6: asecoahuila@asecoahuila.gob.mx | J6: (844) 171 70 00 | K6: Saltillo | L6: Los Fundadores 7269, Col. Ampliación Mirasierra, C.P. 25016 | M6: https://www.asecoahuila.gob.mx/contacto/ | N6: Alta | O6: Órgano técnico del Congreso. Directorio completo en su sección de transparencia.
A7: 6 | B7: Derecho Parlamentario | C7: Órganos autónomos | D7: Media | E7: Instituto Electoral de Coahuila (IEC) | F7: Oficialía de partes | I7: oficialiadepartes@iec.org.mx | J7: (844) 438 62 60 / 800 00 43722 | K7: Saltillo | L7: Blvd. Luis Donaldo Colosio 6207, Col. Las Torrecillas, C.P. 25298 | M7: https://iec.org.mx/v1/ | N7: Alta
A8: 7 | B8: Derecho Parlamentario | C8: Órganos autónomos | D8: Media | E8: Tribunal Electoral del Estado de Coahuila | F8: Contacto general | J8: (844) 439 34 76 / 439 34 77 / 502 21 19 | K8: Saltillo | L8: Blvd. Eulalio Gutiérrez Treviño 551, Fracc. Cruz del Aire, C.P. 25296 | M8: https://www.tecz.org.mx/ | N8: Media | O8: Correo no localizado; revisar tecz.org.mx.
A9: 8 | B9: Ambos | C9: Órganos autónomos | D9: Media | E9: INTRAC – Organismo de Información y Transparencia de Coahuila | F9: Contacto general | I9: intrac@coahuila.gob.mx | J9: (844) 986 98 00 | K9: Saltillo | L9: Perif. Luis Echeverría esq. Eje 2, Centro Metropolitano, C.P. 25020 | M9: https://www.intrac.gob.mx/contactanos/ | N9: Alta | O9: Tiene el directorio de unidades de transparencia de todos los sujetos obligados.
A10: 9 | B10: Maestría DATESP | C10: Derechos humanos | D10: Media | E10: Comisión de los Derechos Humanos del Estado de Coahuila (CDHEC) | F10: Visitaduría General | I10: visitadorgral@cdhec.org.mx | J10: (844) 416 21 10 / 439 36 75 / 800 841 23 00 | K10: Saltillo | L10: Ignacio Allende 226, Zona Centro, C.P. 25000 | M10: https://cdhec.org.mx/v2/Sedes.html | N10: Alta
A11: 10 | B11: Maestría DATESP | C11: Derechos humanos | D11: Baja | E11: Comisión de los Derechos Humanos del Estado de Coahuila (CDHEC) | F11: Primera Visitaduría Regional (Sureste) | I11: primeravisitaduria@cdhec.org.mx | J11: (844) 416 20 50 | K11: Saltillo | M11: https://cdhec.org.mx/v2/Sedes.html | N11: Alta
A12: 11 | B12: Maestría DATESP | C12: Derechos humanos | D12: Baja | E12: Comisión de los Derechos Humanos del Estado de Coahuila (CDHEC) | F12: Segunda Visitaduría Regional (Laguna) | I12: torreon@cdhec.org.mx | J12: (871) 793 03 23 | K12: Torreón | M12: https://cdhec.org.mx/v2/Sedes.html | N12: Alta
A13: 12 | B13: Derecho Parlamentario | C13: Ejecutivo estatal | D13: Media | E13: Secretaría de Gobierno de Coahuila | F13: Conmutador | J13: (844) 411 85 00 / 411 85 88 / 411 86 34 | K13: Saltillo | L13: Palacio de Gobierno, Juárez y Zaragoza s/n, Zona Centro, C.P. 25000 | M13: https://coahuila.gob.mx/dependencias/index/SEGOB | N13: Media | O13: Pedir enlace legislativo y Consejería Jurídica. Titular vigente: ver coahuila.gob.mx/directorio.
A14: 13 | B14: Maestría DATESP | C14: Tecnología / Economía | D14: Media | E14: Secretaría de Economía de Coahuila | F14: Despacho | I14: despacho.sec@coahuila.gob.mx | J14: (844) 415 21 62 / 416 52 74 ext. 4805 | K14: Saltillo | L14: Perif. Luis Echeverría 1560, Torre Saltillo piso 12, Col. Guanajuato Ote., C.P. 25286 | M14: https://www.seccoahuila.gob.mx/directorio.html | N14: Media | O14: Enlace con clústeres e innovación / tecnologías emergentes.
A15: 14 | B15: Ambos | C15: Justicia | D15: Alta | E15: Poder Judicial del Estado de Coahuila | F15: Instituto de Especialización Judicial | I15: instituto.judicial@pjecz.gob.mx | J15: (844) 777 45 38 | K15: Saltillo | L15: Blvd. Los Fundadores 7435, Col. Ex Hacienda San José de los Cerritos, C.P. 25294 | M15: https://www.pjecz.gob.mx/conocenos/estructura/tribunal-superior-de-justicia/organos-no-jurisdiccionales/instituto-de-especializacion-judicial/directorio/ | N15: Alta | O15: Área de capacitación del Poder Judicial: ideal para convenio.
A16: 15 | B16: Ambos | C16: Justicia | D16: Media | E16: Poder Judicial del Estado de Coahuila | F16: Conmutador general | J16: (844) 777 44 98 | K16: Saltillo | L16: Francisco Coss 945, Zona Centro | M16: https://www.pjecz.gob.mx/ | N16: Alta
A17: 16 | B17: Maestría DATESP | C17: Justicia | D17: Media | E17: Tribunal de Justicia Administrativa de Coahuila | F17: Contacto general | J17: (844) 123 03 10 | K17: Saltillo | L17: Blvd. Francisco Coss s/n, Zona Centro, C.P. 25000 | M17: https://tjacoahuila.org/contacto.html | N17: Media | O17: Correo protegido en la página; consultar sitio.
A18: 17 | B18: Maestría DATESP | C18: Procuración de justicia | D18: Alta | E18: Fiscalía General del Estado de Coahuila | F18: Oficinas centrales | J18: (844) 438 07 00 | K18: Saltillo | L18: Humberto Castilla Salas 600, Nuevo Centro Metropolitano, C.P. 25050 | M18: https://sitio.fgecoahuila.gob.mx/contact/ | N18: Alta | O18: Pedir el Centro de Profesionalización, Acreditación, Certificación y Carrera.
A19: 18 | B19: Maestría DATESP | C19: Procuración de justicia | D19: Media | E19: Fiscalía General del Estado de Coahuila | F19: Policía Cibernética (FGE) | I19: policiacibernetica.fge@coahuila.gob.mx | J19: (844) 438 07 00 ext. 7579 | K19: Saltillo | M19: https://www.facebook.com/PoliciaCiberneticaCoahuila | N19: Media | O19: Perfil para tecnologías emergentes / evidencia digital.
A20: 19 | B20: Maestría DATESP | C20: Procuración de justicia | D20: Baja | E20: Fiscalía General del Estado de Coahuila | F20: Delegación Laguna I | J20: (871) 180 12 06 | K20: Torreón | M20: https://fgecoahuila.gob.mx/landing/delegaciones | N20: Media
A21: 20 | B21: Maestría DATESP | C21: Procuración de justicia | D21: Baja | E21: Fiscalía General del Estado de Coahuila | F21: Delegación Sureste | J21: (844) 433 00 23 / 438 76 00 | K21: Saltillo | M21: https://fgecoahuila.gob.mx/landing/delegaciones | N21: Media
A22: 21 | B22: Maestría DATESP | C22: Procuración de justicia | D22: Baja | E22: Fiscalía General del Estado de Coahuila | F22: Delegación Centro | J22: (861) 612 12 49 | K22: Región Centro | M22: https://fgecoahuila.gob.mx/landing/delegaciones | N22: Media | O22: Número de la búsqueda; confirmar clave lada.
A23: 22 | B23: Maestría DATESP | C23: Procuración de justicia | D23: Baja | E23: Fiscalía General del Estado de Coahuila | F23: Delegación Norte II | J23: (877) 773 22 64 | K23: Acuña | M23: https://fgecoahuila.gob.mx/landing/delegaciones | N23: Media
A24: 23 | B24: Maestría DATESP | C24: Procuración de justicia | D24: Baja | E24: Fiscalía General del Estado de Coahuila | F24: Delegación Laguna II | J24: (872) 772 35 45 | K24: San Pedro | M24: https://fgecoahuila.gob.mx/landing/delegaciones | N24: Media
A25: 24 | B25: Maestría DATESP | C25: Seguridad estatal | D25: Alta | E25: Secretaría de Seguridad Pública de Coahuila | F25: Despacho | J25: (844) 438 98 00 ext. 7913 | K25: Saltillo | L25: Perif. Luis Echeverría Álvarez 5402 Int. 1, Centro Metropolitano, C.P. 25050 | M25: https://www.sspcoahuila.gob.mx/directorioSSP.html | N25: Alta | O25: Pedir Dirección de Profesionalización / Recursos Humanos.
A26: 25 | B26: Maestría DATESP | C26: Seguridad estatal | D26: Media | E26: Secretaría de Seguridad Pública de Coahuila | F26: Coordinación Administrativa | J26: (844) 438 98 00 ext. 8047 | K26: Saltillo | M26: https://www.sspcoahuila.gob.mx/directorioSSP.html | N26: Alta
A27: 26 | B27: Maestría DATESP | C27: Seguridad estatal | D27: Media | E27: Secretaría de Seguridad Pública de Coahuila | F27: Policía Cibernética (SSP) | I27: policiacibernetica.ssp@coahuila.gob.mx | J27: (844) 438 98 00 ext. 7946 | K27: Saltillo | M27: https://www.facebook.com/PoliciaCiberneticaCoahuila | N27: Media
A28: 27 | B28: Maestría DATESP | C28: Seguridad estatal | D28: Media | E28: Policía del Estado de Coahuila | F28: Línea general | J28: (844) 438 98 01 | K28: Saltillo | M28: https://www.sspcoahuila.gob.mx/directorioSSP.html | N28: Alta
A29: 28 | B29: Maestría DATESP | C29: Seguridad estatal | D29: Alta | E29: Secretariado Ejecutivo del Sistema Estatal de Seguridad Pública | F29: Contacto general | J29: (844) 438 98 00 | K29: Saltillo | L29: Perif. Luis Echeverría Álvarez 5402 Int. 1, Centro Metropolitano, C.P. 25050 | M29: http://www.secespcoahuila.gob.mx/ | N29: Media | O29: Maneja profesionalización y fondos FASP: clave para becas/convenios.
A30: 29 | B30: Maestría DATESP | C30: Formación policial | D30: Alta | E30: Universidad de Ciencias de la Seguridad – Campus Ramos Arizpe (Academia de Policía) | F30: Dirección | I30: usc.direccion2021@gmail.com | J30: (844) 438 06 99 | K30: Ramos Arizpe | L30: Av. Industria de la Transformación s/n, Parque Industrial Ramos Arizpe, C.P. 25903 | M30: https://sic.cultura.gob.mx/ficha.php?table=universidad&table_id=3256 | N30: Media | O30: Correo Gmail publicado como institucional; confirmar por teléfono.
A31: 30 | B31: Maestría DATESP | C31: Formación policial | D31: Media | E31: Academia de Policía – Sede Matamoros | F31: Contacto | J31: (871) 757 00 61 | K31: Matamoros | L31: Carretera Torreón-Matamoros km 7.5, Ejido San Miguel | M31: https://www.elsiglodetorreon.com.mx/noticia/2025/iniciaran-academias-de-policia-en-todo-coahuila.html | N31: Media
A32: 31 | B32: Maestría DATESP | C32: Seguridad municipal | D32: Alta | E32: Comisaría de Seguridad y Protección Ciudadana de Saltillo | F32: Contacto general | J32: (844) 481 89 30 | K32: Saltillo | L32: Periférico LEA y Blvd. Pérez Treviño s/n, Col. San Ramón | M32: https://www.comisariadeseguridadsaltillo.gob.mx/contacto | N32: Media
A33: 32 | B33: Maestría DATESP | C33: Seguridad municipal | D33: Alta | E33: Dirección de Seguridad Pública Municipal de Torreón | F33: Contacto general | J33: (871) 729 00 99 | K33: Torreón | L33: Periférico Raúl López Sánchez y Av. Bravo s/n, Col. La Amistad | M33: http://policia.torreon.gob.mx/ | N33: Media
A34: 33 | B34: Maestría DATESP | C34: Medio ambiente estatal | D34: Alta | E34: Secretaría de Medio Ambiente de Coahuila (SMA) | F34: Buzón general | I34: buzon@sma.gob.mx | J34: (844) 698 10 98 / 698 10 91 / 698 10 92 | K34: Saltillo | L34: Centro de Gobierno 2º piso, Carr. 57 y Blvd. Centenario de Torreón, C.P. 25294 | M34: https://sma.gob.mx/ | N34: Alta
A35: 34 | B35: Maestría DATESP | C35: Medio ambiente estatal | D35: Alta | E35: Secretaría de Medio Ambiente de Coahuila (SMA) | F35: Subsecretaría de Recursos Naturales | G35: Olga Leticia Rumayor Rodríguez | H35: Subsecretaria | I35: olga.rumayor@coahuila.gob.mx | J35: (844) 698 10 98 ext. 7250 | K35: Saltillo | L35: Centro de Gobierno 2º piso | M35: https://sma.gob.mx/wp-content/uploads/2026/06/IIIDIRECTORIO-JUNIO.pdf | N35: Alta | O35: Directorio oficial de junio 2026.
A36: 35 | B36: Maestría DATESP | C36: Medio ambiente estatal | D36: Alta | E36: Secretaría de Medio Ambiente de Coahuila (SMA) | F36: Subsecretaría de Gestión Ambiental | G36: Santiago Barrios Rosillo | H36: Subsecretario | I36: santiago.barrios@coahuila.gob.mx | J36: (844) 698 10 98 ext. 7252 | K36: Saltillo | L36: Centro de Gobierno 2º piso | M36: https://sma.gob.mx/wp-content/uploads/2026/06/IIIDIRECTORIO-JUNIO.pdf | N36: Alta | O36: Directorio oficial de junio 2026.
A37: 36 | B37: Maestría DATESP | C37: Medio ambiente estatal | D37: Alta | E37: Procuraduría de Protección al Ambiente del Estado de Coahuila (PROPAEC) | F37: Contacto general | J37: (844) 698 10 88 | K37: Saltillo | L37: Centro de Gobierno 2º piso, Carr. 57 km 6.5 | M37: https://mexicoindustry.com/empresa/procuraduria-de-proteccion-al-ambiente-del-estado-de-coahuila | N37: Media | O37: Inspección ambiental estatal.
A38: 37 | B38: Maestría DATESP | C38: Medio ambiente federal | D38: Alta | E38: PROFEPA – Oficina de Representación Coahuila | F38: Encargado de despacho | G38: Raúl Alejandro Araiza Vargas | H38: Encargado de despacho | I38: raul.araiza@profepa.gob.mx | J38: (844) 485 09 83 ext. 18305 | K38: Saltillo | L38: Dr. Lázaro Benavides 835 Nte., Fracc. Nueva España, C.P. 25210 | M38: https://ventanillaunica.economia.gob.mx/media/Directorio%20oficinas%20de%20representaci%C3%B3n%20PROFEPA.pdf | N38: Media | O38: Directorio de 2024; el titular pudo cambiar.
A39: 38 | B39: Maestría DATESP | C39: Medio ambiente federal | D39: Media | E39: SEMARNAT – Oficina de Representación Coahuila | F39: Contacto ciudadano | I39: contacto.ciudadano@semarnat.gob.mx | J39: (844) 439 17 23 / 55 5490 0900 ext. 38401 | K39: Saltillo | L39: Blvd. Saltillo 509, Col. República Oriente, C.P. 25280 (verificar) | M39: https://www.gob.mx/semarnat/acciones-y-programas/directorio-semarnat | N39: Media | O39: Correo nacional; pedir el de la oficina en Coahuila.
A40: 39 | B40: Maestría DATESP | C40: Medio ambiente federal | D40: Media | E40: CONAGUA – Dirección Local Coahuila | F40: Contacto | J40: (844) 171 51 60 ext. 110 | K40: Saltillo | L40: Carr. 57 km 7.5 s/n, Col. El Sauz, C.P. 25294 | M40: https://pnt.conagua.gob.mx/pnt/sgih-gdr/RO/Directorio_UR.pdf | N40: Media | O40: También hay oficina en Torreón (Calz. Manuel Ávila Camacho 2777 Ote.).
...

Sheet Resumen
A1: Segmento | B1: Total contactos | C1: Con correo | D1: Prioridad alta | E1: Derecho Parlamentario | F1: Maestría DATESP | G1: Ambos
A2: Academia (aliados) | B2: =COUNTIF(Directorio!$C$2:$C$62,A2) | C2: =COUNTIFS(Directorio!$C$2:$C$62,A2,Directorio!$I$2:$I$62,"?*") | D2: =COUNTIFS(Directorio!$C$2:$C$62,A2,Directorio!$D$2:$D$62,"Alta") | E2: =COUNTIFS(Directorio!$C$2:$C$62,A2,Directorio!$B$2:$B$62,"Derecho Parlamentario") | F2: =COUNTIFS(Directorio!$C$2:$C$62,A2,Directorio!$B$2:$B$62,"Maestría DATESP") | G2: =COUNTIFS(Directorio!$C$2:$C$62,A2,Directorio!$B$2:$B$62,"Ambos")
A3: Agua | B3: =COUNTIF(Directorio!$C$2:$C$62,A3) | C3: =COUNTIFS(Directorio!$C$2:$C$62,A3,Directorio!$I$2:$I$62,"?*") | D3: =COUNTIFS(Directorio!$C$2:$C$62,A3,Directorio!$D$2:$D$62,"Alta") | E3: =COUNTIFS(Directorio!$C$2:$C$62,A3,Directorio!$B$2:$B$62,"Derecho Parlamentario") | F3: =COUNTIFS(Directorio!$C$2:$C$62,A3,Directorio!$B$2:$B$62,"Maestría DATESP") | G3: =COUNTIFS(Directorio!$C$2:$C$62,A3,Directorio!$B$2:$B$62,"Ambos")
A4: Clústeres | B4: =COUNTIF(Directorio!$C$2:$C$62,A4) | C4: =COUNTIFS(Directorio!$C$2:$C$62,A4,Directorio!$I$2:$I$62,"?*") | D4: =COUNTIFS(Directorio!$C$2:$C$62,A4,Directorio!$D$2:$D$62,"Alta") | E4: =COUNTIFS(Directorio!$C$2:$C$62,A4,Directorio!$B$2:$B$62,"Derecho Parlamentario") | F4: =COUNTIFS(Directorio!$C$2:$C$62,A4,Directorio!$B$2:$B$62,"Maestría DATESP") | G4: =COUNTIFS(Directorio!$C$2:$C$62,A4,Directorio!$B$2:$B$62,"Ambos")
A5: Cámaras empresariales | B5: =COUNTIF(Directorio!$C$2:$C$62,A5) | C5: =COUNTIFS(Directorio!$C$2:$C$62,A5,Directorio!$I$2:$I$62,"?*") | D5: =COUNTIFS(Directorio!$C$2:$C$62,A5,Directorio!$D$2:$D$62,"Alta") | E5: =COUNTIFS(Directorio!$C$2:$C$62,A5,Directorio!$B$2:$B$62,"Derecho Parlamentario") | F5: =COUNTIFS(Directorio!$C$2:$C$62,A5,Directorio!$B$2:$B$62,"Maestría DATESP") | G5: =COUNTIFS(Directorio!$C$2:$C$62,A5,Directorio!$B$2:$B$62,"Ambos")
A6: Derechos humanos | B6: =COUNTIF(Directorio!$C$2:$C$62,A6) | C6: =COUNTIFS(Directorio!$C$2:$C$62,A6,Directorio!$I$2:$I$62,"?*") | D6: =COUNTIFS(Directorio!$C$2:$C$62,A6,Directorio!$D$2:$D$62,"Alta") | E6: =COUNTIFS(Directorio!$C$2:$C$62,A6,Directorio!$B$2:$B$62,"Derecho Parlamentario") | F6: =COUNTIFS(Directorio!$C$2:$C$62,A6,Directorio!$B$2:$B$62,"Maestría DATESP") | G6: =COUNTIFS(Directorio!$C$2:$C$62,A6,Directorio!$B$2:$B$62,"Ambos")
A7: Ejecutivo estatal | B7: =COUNTIF(Directorio!$C$2:$C$62,A7) | C7: =COUNTIFS(Directorio!$C$2:$C$62,A7,Directorio!$I$2:$I$62,"?*") | D7: =COUNTIFS(Directorio!$C$2:$C$62,A7,Directorio!$D$2:$D$62,"Alta") | E7: =COUNTIFS(Directorio!$C$2:$C$62,A7,Directorio!$B$2:$B$62,"Derecho Parlamentario") | F7: =COUNTIFS(Directorio!$C$2:$C$62,A7,Directorio!$B$2:$B$62,"Maestría DATESP") | G7: =COUNTIFS(Directorio!$C$2:$C$62,A7,Directorio!$B$2:$B$62,"Ambos")
A8: Fiscalización | B8: =COUNTIF(Directorio!$C$2:$C$62,A8) | C8: =COUNTIFS(Directorio!$C$2:$C$62,A8,Directorio!$I$2:$I$62,"?*") | D8: =COUNTIFS(Directorio!$C$2:$C$62,A8,Directorio!$D$2:$D$62,"Alta") | E8: =COUNTIFS(Directorio!$C$2:$C$62,A8,Directorio!$B$2:$B$62,"Derecho Parlamentario") | F8: =COUNTIFS(Directorio!$C$2:$C$62,A8,Directorio!$B$2:$B$62,"Maestría DATESP") | G8: =COUNTIFS(Directorio!$C$2:$C$62,A8,Directorio!$B$2:$B$62,"Ambos")
A9: Formación policial | B9: =COUNTIF(Directorio!$C$2:$C$62,A9) | C9: =COUNTIFS(Directorio!$C$2:$C$62,A9,Directorio!$I$2:$I$62,"?*") | D9: =COUNTIFS(Directorio!$C$2:$C$62,A9,Directorio!$D$2:$D$62,"Alta") | E9: =COUNTIFS(Directorio!$C$2:$C$62,A9,Directorio!$B$2:$B$62,"Derecho Parlamentario") | F9: =COUNTIFS(Directorio!$C$2:$C$62,A9,Directorio!$B$2:$B$62,"Maestría DATESP") | G9: =COUNTIFS(Directorio!$C$2:$C$62,A9,Directorio!$B$2:$B$62,"Ambos")
A10: Justicia | B10: =COUNTIF(Directorio!$C$2:$C$62,A10) | C10: =COUNTIFS(Directorio!$C$2:$C$62,A10,Directorio!$I$2:$I$62,"?*") | D10: =COUNTIFS(Directorio!$C$2:$C$62,A10,Directorio!$D$2:$D$62,"Alta") | E10: =COUNTIFS(Directorio!$C$2:$C$62,A10,Directorio!$B$2:$B$62,"Derecho Parlamentario") | F10: =COUNTIFS(Directorio!$C$2:$C$62,A10,Directorio!$B$2:$B$62,"Maestría DATESP") | G10: =COUNTIFS(Directorio!$C$2:$C$62,A10,Directorio!$B$2:$B$62,"Ambos")
A11: Legislativo | B11: =COUNTIF(Directorio!$C$2:$C$62,A11) | C11: =COUNTIFS(Directorio!$C$2:$C$62,A11,Directorio!$I$2:$I$62,"?*") | D11: =COUNTIFS(Directorio!$C$2:$C$62,A11,Directorio!$D$2:$D$62,"Alta") | E11: =COUNTIFS(Directorio!$C$2:$C$62,A11,Directorio!$B$2:$B$62,"Derecho Parlamentario") | F11: =COUNTIFS(Directorio!$C$2:$C$62,A11,Directorio!$B$2:$B$62,"Maestría DATESP") | G11: =COUNTIFS(Directorio!$C$2:$C$62,A11,Directorio!$B$2:$B$62,"Ambos")
A12: Medio ambiente estatal | B12: =COUNTIF(Directorio!$C$2:$C$62,A12) | C12: =COUNTIFS(Directorio!$C$2:$C$62,A12,Directorio!$I$2:$I$62,"?*") | D12: =COUNTIFS(Directorio!$C$2:$C$62,A12,Directorio!$D$2:$D$62,"Alta") | E12: =COUNTIFS(Directorio!$C$2:$C$62,A12,Directorio!$B$2:$B$62,"Derecho Parlamentario") | F12: =COUNTIFS(Directorio!$C$2:$C$62,A12,Directorio!$B$2:$B$62,"Maestría DATESP") | G12: =COUNTIFS(Directorio!$C$2:$C$62,A12,Directorio!$B$2:$B$62,"Ambos")
A13: Medio ambiente federal | B13: =COUNTIF(Directorio!$C$2:$C$62,A13) | C13: =COUNTIFS(Directorio!$C$2:$C$62,A13,Directorio!$I$2:$I$62,"?*") | D13: =COUNTIFS(Directorio!$C$2:$C$62,A13,Directorio!$D$2:$D$62,"Alta") | E13: =COUNTIFS(Directorio!$C$2:$C$62,A13,Directorio!$B$2:$B$62,"Derecho Parlamentario") | F13: =COUNTIFS(Directorio!$C$2:$C$62,A13,Directorio!$B$2:$B$62,"Maestría DATESP") | G13: =COUNTIFS(Directorio!$C$2:$C$62,A13,Directorio!$B$2:$B$62,"Ambos")
... A20: Órganos autónomos | B20: =COUNTIF(Directorio!$C$2:$C$62,A20) | C20: =COUNTIFS(Directorio!$C$2:$C$62,A20,Directorio!$I$2:$I$62,"?*") | D20: =COUNTIFS(Directorio!$C$2:$C$62,A20,Directorio!$D$2:$D$62,"Alta") | E20: =COUNTIFS(Directorio!$C$2:$C$62,A20,Directorio!$B$2:$B$62,"Derecho Parlamentario") | F20: =COUNTIFS(Directorio!$C$2:$C$62,A20,Directorio!$B$2:$B$62,"Maestría DATESP") | G20: =COUNTIFS(Directorio!$C$2:$C$62,A20,Directorio!$B$2:$B$62,"Ambos")
A21: TOTAL | B21: =SUM(B2:B20) | C21: =SUM(C2:C20) | D21: =SUM(D2:D20) | E21: =SUM(E2:E20) | F21: =SUM(F2:F20) | G21: =SUM(G2:G20)
A23: Nota: 'Ambos' = contacto útil para los cursos de Derecho Parlamentario y para la Maestría.

Sheet Pendientes
A1: Segmento | B1: Institución / grupo | C1: Qué falta conseguir | D1: Dónde buscar | E1: Responsable | F1: Estatus
A2: Legislativo | B2: Congreso de Coahuila | C2: Correo y extensión de cada uno de los 25 diputados (y diputados electos 2027) | D2: congresocoahuila.gob.mx/portal/diputados/
A3: Legislativo | B3: Congreso de Coahuila | C3: Secretaría de Servicios Parlamentarios, Unidad de Transparencia, área de RR. HH. | D3: congresocoahuila.gob.mx → Información pública de oficio
A4: Legislativo | B4: Diputados federales y senadores por Coahuila | C4: Correos institucionales | D4: diputados.gob.mx / senado.gob.mx
A5: Municipal | B5: 38 ayuntamientos | C5: Regidores, síndicos, secretario del ayuntamiento, director jurídico | D5: Sitio de cada municipio y Coahuila Transparente
A6: Ejecutivo estatal | B6: Consejería Jurídica del Estado | C6: Titular y correo | D6: coahuila.gob.mx/directorio
A7: Seguridad estatal | B7: SSP Coahuila | C7: Dirección de Profesionalización / Carrera Policial | D7: sspcoahuila.gob.mx/directorioSSP.html
A8: Seguridad | B8: C4/C5 estatal | C8: Área administrativa y de capacitación | D8: SSP Coahuila / Secretariado Ejecutivo
A9: Seguridad municipal | B9: Monclova, Piedras Negras, Acuña, Ramos Arizpe, Matamoros, San Pedro, Frontera, Sabinas | C9: Directores de seguridad pública municipal | D9: Sitios municipales
A10: Procuración de justicia | B10: Fiscalía General del Estado | C10: Centro de Profesionalización, Acreditación, Certificación y Carrera; fiscalía de delitos ambientales | D10: sitio.fgecoahuila.gob.mx
A11: Justicia | B11: Defensoría Jurídica / Defensoría Pública | C11: Área de capacitación | D11: coahuila.gob.mx/directorio
A12: Empresas | B12: Armadoras y proveedores automotrices (Saltillo–Ramos Arizpe–Derramadero) | C12: Gerentes EHS, Legal/Compliance, Seguridad patrimonial, RR. HH./Capacitación | D12: LinkedIn de la empresa + CIAC
A13: Empresas | B13: Minero-metalúrgicas y acereras (Torreón, Monclova, región Carbonífera) | C13: Gerentes de medio ambiente, seguridad, legal | D13: LinkedIn + Clúster de Energía/Minero
... A19: Seguridad privada | B19: Empresas de seguridad privada autorizadas | C19: Directores y RR. HH. | D19: Padrón de la SSP Coahuila (RETYS)
